Workbook

Sheet Matriz
J1: Articulacion | W1: Regulada
A2: LINEA | B2: CONSECUTIVO | C2: OBSERVACIONES | D2: MARCA | E2: MODELO | F2: SERIAL | G2: CANTIDAD | H2: COSTO UNITARIO | I2: OTROSCOSTOS | J2: 3425230 ASISTENCIA ADMINISTRATIVA | K2: 3425227 ASISTENCIA ADMINISTRATIVA | L2: 3425495 ASISTENCIA ADMINISTRATIVA | M2: 3425231 CONTABILIZACION DE OPERACIONES COMERCIALES Y FINANCIERAS | N2: 3425503 CONTABILIZACION DE OPERACIONES COMERCIALES Y FINANCIERAS | O2: 3425505 CONTABILIZACION DE OPERACIONES COMERCIALES Y FINANCIERAS | P2: 3425511 VENTA DE PRODUCTOS EN LINEA | Q2: 3425209 CONSERVACION DE RECURSOS NATURALES | R2: 3425210 CONSERVACION DE RECURSOS NATURALES | S2: 3425504 CONSERVACION DE RECURSOS NATURALES | T2: 3425222 MONITOREO AMBIENTAL | U2: TOTAL SALIDA ARTICULACIÓN | V2: FILA ARTICULACIÓN (ref.) | W2: 3409954 ASISTENCIA EN ORGANIZACION DE ARCHIVOS . | X2: 3554431 ASISTENCIA EN ORGANIZACION DE ARCHIVOS . | Y2: 3225901 GESTIÓN ADMINISTRATIVA | Z2: 3387728 GESTIÓN ADMINISTRATIVA | AA2: 3409966 GESTIÓN ADMINISTRATIVA | AB2: 3488746 GESTIÓN ADMINISTRATIVA | AC2: 3518069 GESTIÓN ADMINISTRATIVA | AD2: 3276454 GESTIÓN EMPRESARIAL | AE2: 3404023 ASISTENCIA ADMINISTRATIVA . | AF2: 3453974 ASISTENCIA ADMINISTRATIVA . | AG2: 3485255 COORDINACION EN SISTEMAS INTEGRADOS DE GESTION | AH2: 3488730 OPERACIONES DE COMERCIO EXTERIOR | AI2: 3269063 GESTION CONTABLE Y DE INFORMACION FINANCIERA | AJ2: 3279088 GESTION CONTABLE Y DE INFORMACION FINANCIERA | AK2: 3387727 GESTION CONTABLE Y DE INFORMACION FINANCIERA | AL2: 3407377 GESTION CONTABLE Y DE INFORMACION FINANCIERA | AM2: 3409967 GESTION CONTABLE Y DE INFORMACION FINANCIERA | AN2: 3488739 GESTION CONTABLE Y DE INFORMACION FINANCIERA | AO2: 3311563 APOYO ADMINISTRATIVO EN SALUD. | AP2: 3488725 APOYO ADMINISTRATIVO EN SALUD. | AQ2: 3409965 ATENCION INTEGRAL A LA PRIMERA INFANCIA | AR2: 3529543 ATENCION INTEGRAL A LA PRIMERA INFANCIA | AS2: 3311550 ENFERMERIA. | AT2: 3488712 ENFERMERIA. | AU2: 3423692 PROMOTOR DE SALUD | AV2: 3444274 PROMOTOR DE SALUD | AW2: 3447193 INTERPRETACION DE INSTRUMENTOS MUSICALES. | AX2: Total salida Regulada | AY2: Saldo
A3: 27 | B3: 250071 | C3: Banderín festón de alta calidad material tela resistente a exteriores, color: surtido, blanco-Verde. Paquete de 7 metros por 2 unidades. | D3: NA | E3: NA | F3: NA | G3: 7 | H3: 29411.76 | I3: 0 | J3: {=IF($V3="","",IFERROR(INDEX(Articulacion!G:G,$V3),0))} | K3: {=IF($V3="","",IFERROR(INDEX(Articulacion!H:H,$V3),0))} | L3: {=IF($V3="","",IFERROR(INDEX(Articulacion!I:I,$V3),0))} | M3: {=IF($V3="","",IFERROR(INDEX(Articulacion!J:J,$V3),0))} | N3: {=IF($V3="","",IFERROR(INDEX(Articulacion!K:K,$V3),0))} | O3: {=IF($V3="","",IFERROR(INDEX(Articulacion!L:L,$V3),0))} | P3: {=IF($V3="","",IFERROR(INDEX(Articulacion!M:M,$V3),0))} | Q3: {=IF($V3="","",IFERROR(INDEX(Articulacion!N:N,$V3),0))} | R3: {=IF($V3="","",IFERROR(INDEX(Articulacion!O:O,$V3),0))} | S3: {=IF($V3="","",IFERROR(INDEX(Articulacion!P:P,$V3),0))} | T3: {=IF($V3="","",IFERROR(INDEX(Articulacion!Q:Q,$V3),0))} | U3: =IF($V3="",0,SUM(J3:T3)) -> 0 | AQ3: 3 | AR3: 4 | AX3: =SUM(W3:AW3) -> 7 | AY3: =G3-U3-AX3 -> 0
A4: 84 | B4: 292251 | C4: BANDERITAS, X5, COLORES, 1.2X4.5CM X125HJS | D4: NA | E4: NA | F4: NA | G4: 17 | H4: 4621.85 | I4: 0 | J4: {=IF($V4="","",IFERROR(INDEX(Articulacion!G:G,$V4),0))} | K4: {=IF($V4="","",IFERROR(INDEX(Articulacion!H:H,$V4),0))} | L4: {=IF($V4="","",IFERROR(INDEX(Articulacion!I:I,$V4),0))} | M4: {=IF($V4="","",IFERROR(INDEX(Articulacion!J:J,$V4),0))} | N4: {=IF($V4="","",IFERROR(INDEX(Articulacion!K:K,$V4),0))} | O4: {=IF($V4="","",IFERROR(INDEX(Articulacion!L:L,$V4),0))} | P4: {=IF($V4="","",IFERROR(INDEX(Articulacion!M:M,$V4),0))} | Q4: {=IF($V4="","",IFERROR(INDEX(Articulacion!N:N,$V4),0))} | R4: {=IF($V4="","",IFERROR(INDEX(Articulacion!O:O,$V4),0))} | S4: {=IF($V4="","",IFERROR(INDEX(Articulacion!P:P,$V4),0))} | T4: {=IF($V4="","",IFERROR(INDEX(Articulacion!Q:Q,$V4),0))} | U4: =IF($V4="",0,SUM(J4:T4)) -> 0 | AG4: 1 | AH4: 1 | AI4: 1 | AJ4: 1 | AK4: 1 | AL4: 1 | AM4: 1 | AN4: 2 | AO4: 1 | AP4: 1 | AQ4: 1 | AR4: 1 | AS4: 1 | AT4: 1 | AU4: 1 | AV4: 1 | AX4: =SUM(W4:AW4) -> 17 | AY4: =G4-U4-AX4 -> 0
A5: 83 | B5: 292165 | C5: Barra Silicona Delgada X 50 | D5: NA | E5: NA | F5: NA | G5: 3 | H5: 1680.67 | I5: 0 | J5: {=IF($V5="","",IFERROR(INDEX(Articulacion!G:G,$V5),0))} | K5: {=IF($V5="","",IFERROR(INDEX(Articulacion!H:H,$V5),0))} | L5: {=IF($V5="","",IFERROR(INDEX(Articulacion!I:I,$V5),0))} | M5: {=IF($V5="","",IFERROR(INDEX(Articulacion!J:J,$V5),0))} | N5: {=IF($V5="","",IFERROR(INDEX(Articulacion!K:K,$V5),0))} | O5: {=IF($V5="","",IFERROR(INDEX(Articulacion!L:L,$V5),0))} | P5: {=IF($V5="","",IFERROR(INDEX(Articulacion!M:M,$V5),0))} | Q5: {=IF($V5="","",IFERROR(INDEX(Articulacion!N:N,$V5),0))} | R5: {=IF($V5="","",IFERROR(INDEX(Articulacion!O:O,$V5),0))} | S5: {=IF($V5="","",IFERROR(INDEX(Articulacion!P:P,$V5),0))} | T5: {=IF($V5="","",IFERROR(INDEX(Articulacion!Q:Q,$V5),0))} | U5: =IF($V5="",0,SUM(J5:T5)) -> 0 | AB5: 1 | AC5: 1 | AD5: 1 | AX5: =SUM(W5:AW5) -> 3 | AY5: =G5-U5-AX5 -> 0
A6: 82 | B6: 249127 | C6: Barras de pegante libres de ácido. Pegante Barra 40 Gr | D6: NA | E6: NA | F6: NA | G6: 12 | H6: 10084.03 | I6: 0 | J6: {=IF($V6="","",IFERROR(INDEX(Articulacion!G:G,$V6),0))} | K6: {=IF($V6="","",IFERROR(INDEX(Articulacion!H:H,$V6),0))} | L6: {=IF($V6="","",IFERROR(INDEX(Articulacion!I:I,$V6),0))} | M6: {=IF($V6="","",IFERROR(INDEX(Articulacion!J:J,$V6),0))} | N6: {=IF($V6="","",IFERROR(INDEX(Articulacion!K:K,$V6),0))} | O6: {=IF($V6="","",IFERROR(INDEX(Articulacion!L:L,$V6),0))} | P6: {=IF($V6="","",IFERROR(INDEX(Articulacion!M:M,$V6),0))} | Q6: {=IF($V6="","",IFERROR(INDEX(Articulacion!N:N,$V6),0))} | R6: {=IF($V6="","",IFERROR(INDEX(Articulacion!O:O,$V6),0))} | S6: {=IF($V6="","",IFERROR(INDEX(Articulacion!P:P,$V6),0))} | T6: {=IF($V6="","",IFERROR(INDEX(Articulacion!Q:Q,$V6),0))} | U6: =IF($V6="",0,SUM(J6:T6)) -> 0 | AM6: 1 | AN6: 2 | AO6: 1 | AP6: 1 | AQ6: 1 | AR6: 1 | AS6: 1 | AT6: 1 | AU6: 1 | AV6: 1 | AW6: 1 | AX6: =SUM(W6:AW6) -> 12 | AY6: =G6-U6-AX6 -> 0
A7: 19 | B7: 290543 | C7: Barras de pegante sólido, composición: Adhesivo sintético libre de ácido (acid-free), no tóxico, barra en tubo plástico con mecanismo giratorio, contenido por barra: Entre 8 g y 12 g, material del envase plástico resistente con tapa de seguridad, secado rápido, limpio y sin residuos. Apto para papel, cartulina, cartón delgado y materiales escolares. Apto para uso escolar. Presentación individual | D7: NA | E7: NA | F7: NA | G7: 10 | H7: 5042.02 | I7: 0 | J7: {=IF($V7="","",IFERROR(INDEX(Articulacion!G:G,$V7),0))} | K7: {=IF($V7="","",IFERROR(INDEX(Articulacion!H:H,$V7),0))} | L7: {=IF($V7="","",IFERROR(INDEX(Articulacion!I:I,$V7),0))} | M7: {=IF($V7="","",IFERROR(INDEX(Articulacion!J:J,$V7),0))} | N7: {=IF($V7="","",IFERROR(INDEX(Articulacion!K:K,$V7),0))} | O7: {=IF($V7="","",IFERROR(INDEX(Articulacion!L:L,$V7),0))} | P7: {=IF($V7="","",IFERROR(INDEX(Articulacion!M:M,$V7),0))} | Q7: {=IF($V7="","",IFERROR(INDEX(Articulacion!N:N,$V7),0))} | R7: {=IF($V7="","",IFERROR(INDEX(Articulacion!O:O,$V7),0))} | S7: {=IF($V7="","",IFERROR(INDEX(Articulacion!P:P,$V7),0))} | T7: {=IF($V7="","",IFERROR(INDEX(Articulacion!Q:Q,$V7),0))} | U7: =IF($V7="",0,SUM(J7:T7)) -> 0 | AN7: 1 | AO7: 1 | AP7: 1 | AQ7: 1 | AR7: 1 | AS7: 1 | AT7: 1 | AU7: 1 | AV7: 1 | AW7: 1 | AX7: =SUM(W7:AW7) -> 10 | AY7: =G7-U7-AX7 -> 0
A8: 81 | B8: 290628 | C8: Billetes y monedas didácticos pesos colombianos, impresos a color por ambos lados denominaciones $ 1000, $2000, $5000, $10.000, $20.000, $50.000 y $100.000. Medidas aproximadas 12 cm x 7 cm. Incluye 94 unidades de billetes surtidos y 80 unidades de monedas de cartón surtidas. | D8: NA | E8: NA | F8: NA | G8: 20 | H8: 10084.03 | I8: 0 | J8: {=IF($V8="","",IFERROR(INDEX(Articulacion!G:G,$V8),0))} -> 0 | K8: {=IF($V8="","",IFERROR(INDEX(Articulacion!H:H,$V8),0))} -> 0 | L8: {=IF($V8="","",IFERROR(INDEX(Articulacion!I:I,$V8),0))} -> 0 | M8: {=IF($V8="","",IFERROR(INDEX(Articulacion!J:J,$V8),0))} -> 2 | N8: {=IF($V8="","",IFERROR(INDEX(Articulacion!K:K,$V8),0))} -> 2 | O8: {=IF($V8="","",IFERROR(INDEX(Articulacion!L:L,$V8),0))} -> 2 | P8: {=IF($V8="","",IFERROR(INDEX(Articulacion!M:M,$V8),0))} -> 2 | Q8: {=IF($V8="","",IFERROR(INDEX(Articulacion!N:N,$V8),0))} -> 0 | R8: {=IF($V8="","",IFERROR(INDEX(Articulacion!O:O,$V8),0))} -> 0 | S8: {=IF($V8="","",IFERROR(INDEX(Articulacion!P:P,$V8),0))} -> 0 | T8: {=IF($V8="","",IFERROR(INDEX(Articulacion!Q:Q,$V8),0))} -> 0 | U8: =IF($V8="",0,SUM(J8:T8)) -> 8 | V8: 2 | Y8: 1 | Z8: 1 | AA8: 1 | AB8: 1 | AC8: 1 | AD8: 1 | AE8: 1 | AF8: 1 | AG8: 1 | AH8: 1 | AI8: 1 | AJ8: 1 | AX8: =SUM(W8:AW8) -> 12 | AY8: =G8-U8-AX8 -> 0
A9: 80 | B9: 275696 | C9: Bisturí material del mango plástico, cuchilla en acero inoxidable, medida de cuchilla es de 18 mm con traba de seguridad. | D9: NA | E9: NA | F9: NA | G9: 10 | H9: 13445.38 | I9: 0 | J9: {=IF($V9="","",IFERROR(INDEX(Articulacion!G:G,$V9),0))} | K9: {=IF($V9="","",IFERROR(INDEX(Articulacion!H:H,$V9),0))} | L9: {=IF($V9="","",IFERROR(INDEX(Articulacion!I:I,$V9),0))} | M9: {=IF($V9="","",IFERROR(INDEX(Articulacion!J:J,$V9),0))} | N9: {=IF($V9="","",IFERROR(INDEX(Articulacion!K:K,$V9),0))} | O9: {=IF($V9="","",IFERROR(INDEX(Articulacion!L:L,$V9),0))} | P9: {=IF($V9="","",IFERROR(INDEX(Articulacion!M:M,$V9),0))} | Q9: {=IF($V9="","",IFERROR(INDEX(Articulacion!N:N,$V9),0))} | R9: {=IF($V9="","",IFERROR(INDEX(Articulacion!O:O,$V9),0))} | S9: {=IF($V9="","",IFERROR(INDEX(Articulacion!P:P,$V9),0))} | T9: {=IF($V9="","",IFERROR(INDEX(Articulacion!Q:Q,$V9),0))} | U9: =IF($V9="",0,SUM(J9:T9)) -> 0 | W9: 1 | X9: 1 | Y9: 1 | Z9: 1 | AA9: 1 | AB9: 1 | AC9: 1 | AD9: 1 | AE9: 1 | AF9: 1 | AX9: =SUM(W9:AW9) -> 10 | AY9: =G9-U9-AX9 -> 0
A10: 79 | B10: 298522 | C10: Block cuadriculado 1/8. Block de papel cuadriculado tamaño oficio X 80 hojas | D10: NA | E10: NA | F10: NA | G10: 12 | H10: 11764.71 | I10: 0 | J10: {=IF($V10="","",IFERROR(INDEX(Articulacion!G:G,$V10),0))} | K10: {=IF($V10="","",IFERROR(INDEX(Articulacion!H:H,$V10),0))} | L10: {=IF($V10="","",IFERROR(INDEX(Articulacion!I:I,$V10),0))} | M10: {=IF($V10="","",IFERROR(INDEX(Articulacion!J:J,$V10),0))} | N10: {=IF($V10="","",IFERROR(INDEX(Articulacion!K:K,$V10),0))} | O10: {=IF($V10="","",IFERROR(INDEX(Articulacion!L:L,$V10),0))} | P10: {=IF($V10="","",IFERROR(INDEX(Articulacion!M:M,$V10),0))} | Q10: {=IF($V10="","",IFERROR(INDEX(Articulacion!N:N,$V10),0))} | R10: {=IF($V10="","",IFERROR(INDEX(Articulacion!O:O,$V10),0))} | S10: {=IF($V10="","",IFERROR(INDEX(Articulacion!P:P,$V10),0))} | T10: {=IF($V10="","",IFERROR(INDEX(Articulacion!Q:Q,$V10),0))} | U10: =IF($V10="",0,SUM(J10:T10)) -> 0 | AG10: 1 | AH10: 1 | AI10: 1 | AJ10: 1 | AK10: 1 | AL10: 1 | AM10: 1 | AN10: 2 | AO10: 1 | AP10: 1 | AQ10: 1 | AX10: =SUM(W10:AW10) -> 12 | AY10: =G10-U10-AX10 -> 0
A11: 78 | B11: 239037 | C11: Block papel Iris tamaño, oficio X 30 hojas | D11: NA | E11: NA | F11: NA | G11: 18 | H11: 10924.37 | I11: 0 | J11: {=IF($V11="","",IFERROR(INDEX(Articulacion!G:G,$V11),0))} | K11: {=IF($V11="","",IFERROR(INDEX(Articulacion!H:H,$V11),0))} | L11: {=IF($V11="","",IFERROR(INDEX(Articulacion!I:I,$V11),0))} | M11: {=IF($V11="","",IFERROR(INDEX(Articulacion!J:J,$V11),0))} | N11: {=IF($V11="","",IFERROR(INDEX(Articulacion!K:K,$V11),0))} | O11: {=IF($V11="","",IFERROR(INDEX(Articulacion!L:L,$V11),0))} | P11: {=IF($V11="","",IFERROR(INDEX(Articulacion!M:M,$V11),0))} | Q11: {=IF($V11="","",IFERROR(INDEX(Articulacion!N:N,$V11),0))} | R11: {=IF($V11="","",IFERROR(INDEX(Articulacion!O:O,$V11),0))} | S11: {=IF($V11="","",IFERROR(INDEX(Articulacion!P:P,$V11),0))} | T11: {=IF($V11="","",IFERROR(INDEX(Articulacion!Q:Q,$V11),0))} | U11: =IF($V11="",0,SUM(J11:T11)) -> 0 | W11: 1 | X11: 1 | Y11: 1 | Z11: 1 | AA11: 1 | AB11: 1 | AC11: 1 | AD11: 1 | AE11: 1 | AF11: 1 | AG11: 1 | AH11: 1 | AI11: 1 | AJ11: 1 | AK11: 1 | AL11: 1 | AM11: 1 | AN11: 1 | AX11: =SUM(W11:AW11) -> 18 | AY11: =G11-U11-AX11 -> 0
A12: 32 | B12: 274294 | C12: Bolígrafo de punta fina o media, Color de tinta: Morado, base de aceite o gel de secado rápido, no tóxica, Punta media: 1.0 mm y/o Punta fina: 0.7 mm. cuerpo: Plástico resistente, ergonómico, con clip para sujeción, con tapa de seguridad o mecanismo retráctil, flujo de tinta continuo, uniforme y sin saltos. Caja por 12 unidades | D12: NA | E12: NA | F12: NA | G12: 2 | H12: 35294.12 | I12: 0 | J12: {=IF($V12="","",IFERROR(INDEX(Articulacion!G:G,$V12),0))} | K12: {=IF($V12="","",IFERROR(INDEX(Articulacion!H:H,$V12),0))} | L12: {=IF($V12="","",IFERROR(INDEX(Articulacion!I:I,$V12),0))} | M12: {=IF($V12="","",IFERROR(INDEX(Articulacion!J:J,$V12),0))} | N12: {=IF($V12="","",IFERROR(INDEX(Articulacion!K:K,$V12),0))} | O12: {=IF($V12="","",IFERROR(INDEX(Articulacion!L:L,$V12),0))} | P12: {=IF($V12="","",IFERROR(INDEX(Articulacion!M:M,$V12),0))} | Q12: {=IF($V12="","",IFERROR(INDEX(Articulacion!N:N,$V12),0))} | R12: {=IF($V12="","",IFERROR(INDEX(Articulacion!O:O,$V12),0))} | S12: {=IF($V12="","",IFERROR(INDEX(Articulacion!P:P,$V12),0))} | T12: {=IF($V12="","",IFERROR(INDEX(Articulacion!Q:Q,$V12),0))} | U12: =IF($V12="",0,SUM(J12:T12)) -> 0 | Y12: 1 | Z12: 1 | AX12: =SUM(W12:AW12) -> 2 | AY12: =G12-U12-AX12 -> 0
A13: 77 | B13: 292235 | C13: BOLÍGRAFO NEGRO, caja por 12 unidades, barril triangular transparente, punta de 1.0 mm (o 0.7 mm fino) y sistema de tinta InkJoy, secado rápido, tapa con clip y tinta negra intensa. | D13: NA | E13: NA | F13: NA | G13: 18 | H13: 10084.03 | I13: 0 | J13: {=IF($V13="","",IFERROR(INDEX(Articulacion!G:G,$V13),0))} | K13: {=IF($V13="","",IFERROR(INDEX(Articulacion!H:H,$V13),0))} | L13: {=IF($V13="","",IFERROR(INDEX(Articulacion!I:I,$V13),0))} | M13: {=IF($V13="","",IFERROR(INDEX(Articulacion!J:J,$V13),0))} | N13: {=IF($V13="","",IFERROR(INDEX(Articulacion!K:K,$V13),0))} | O13: {=IF($V13="","",IFERROR(INDEX(Articulacion!L:L,$V13),0))} | P13: {=IF($V13="","",IFERROR(INDEX(Articulacion!M:M,$V13),0))} | Q13: {=IF($V13="","",IFERROR(INDEX(Articulacion!N:N,$V13),0))} | R13: {=IF($V13="","",IFERROR(INDEX(Articulacion!O:O,$V13),0))} | S13: {=IF($V13="","",IFERROR(INDEX(Articulacion!P:P,$V13),0))} | T13: {=IF($V13="","",IFERROR(INDEX(Articulacion!Q:Q,$V13),0))} | U13: =IF($V13="",0,SUM(J13:T13)) -> 0 | AG13: 1 | AH13: 1 | AI13: 1 | AJ13: 1 | AK13: 1 | AL13: 1 | AM13: 1 | AN13: 2 | AO13: 1 | AP13: 1 | AQ13: 1 | AR13: 1 | AS13: 1 | AT13: 1 | AU13: 1 | AV13: 1 | AW13: 1 | AX13: =SUM(W13:AW13) -> 18 | AY13: =G13-U13-AX13 -> 0
A14: 76 | B14: 244261 | C14: Borrador para tablero acrílico, en madera o plástico | D14: NA | E14: NA | F14: NA | G14: 15 | H14: 4621.85 | I14: 0 | J14: {=IF($V14="","",IFERROR(INDEX(Articulacion!G:G,$V14),0))} | K14: {=IF($V14="","",IFERROR(INDEX(Articulacion!H:H,$V14),0))} | L14: {=IF($V14="","",IFERROR(INDEX(Articulacion!I:I,$V14),0))} | M14: {=IF($V14="","",IFERROR(INDEX(Articulacion!J:J,$V14),0))} | N14: {=IF($V14="","",IFERROR(INDEX(Articulacion!K:K,$V14),0))} | O14: {=IF($V14="","",IFERROR(INDEX(Articulacion!L:L,$V14),0))} | P14: {=IF($V14="","",IFERROR(INDEX(Articulacion!M:M,$V14),0))} | Q14: {=IF($V14="","",IFERROR(INDEX(Articulacion!N:N,$V14),0))} | R14: {=IF($V14="","",IFERROR(INDEX(Articulacion!O:O,$V14),0))} | S14: {=IF($V14="","",IFERROR(INDEX(Articulacion!P:P,$V14),0))} | T14: {=IF($V14="","",IFERROR(INDEX(Articulacion!Q:Q,$V14),0))} | U14: =IF($V14="",0,SUM(J14:T14)) -> 0 | W14: 1 | X14: 1 | Y14: 1 | Z14: 1 | AA14: 1 | AB14: 1 | AC14: 1 | AD14: 1 | AE14: 1 | AF14: 1 | AG14: 1 | AH14: 1 | AI14: 1 | AJ14: 1 | AK14: 1 | AX14: =SUM(W14:AW14) -> 15 | AY14: =G14-U14-AX14 -> 0
A15: 92 | B15: 292245 | C15: Caja para archivo tipo troquelada x 100 en cartón corrugado tipo nevera reglamentaria en cartón C 650, tamaño: alto 40 cm, ancho 10.5 cm, largo 26 cm, rotulada, sistema doble ventilación | D15: NA | E15: NA | F15: NA | G15: 20 | H15: 14285.71 | I15: 0 | J15: {=IF($V15="","",IFERROR(INDEX(Articulacion!G:G,$V15),0))} | K15: {=IF($V15="","",IFERROR(INDEX(Articulacion!H:H,$V15),0))} | L15: {=IF($V15="","",IFERROR(INDEX(Articulacion!I:I,$V15),0))} | M15: {=IF($V15="","",IFERROR(INDEX(Articulacion!J:J,$V15),0))} | N15: {=IF($V15="","",IFERROR(INDEX(Articulacion!K:K,$V15),0))} | O15: {=IF($V15="","",IFERROR(INDEX(Articulacion!L:L,$V15),0))} | P15: {=IF($V15="","",IFERROR(INDEX(Articulacion!M:M,$V15),0))} | Q15: {=IF($V15="","",IFERROR(INDEX(Articulacion!N:N,$V15),0))} | R15: {=IF($V15="","",IFERROR(INDEX(Articulacion!O:O,$V15),0))} | S15: {=IF($V15="","",IFERROR(INDEX(Articulacion!P:P,$V15),0))} | T15: {=IF($V15="","",IFERROR(INDEX(Articulacion!Q:Q,$V15),0))} | U15: =IF($V15="",0,SUM(J15:T15)) -> 0 | W15: 5 | X15: 5 | Y15: 2 | Z15: 2 | AA15: 1 | AB15: 1 | AC15: 1 | AD15: 1 | AE15: 1 | AF15: 1 | AX15: =SUM(W15:AW15) -> 20 | AY15: =G15-U15-AX15 -> 0
A16: 91 | B16: 298052 | C16: Caja para archivo tipo troquelada X 300, resistente, abertura para sujetar y transportar con facilidad, cartón nuevo calibre 720, color Kraft, sistema ideal para evitar que se deforme o se desfonde caja con tapa. Medidas: Alto 26 Centímetro, largo 40 Centímetro. Ancho 30 centímetros. | D16: NA | E16: NA | F16: NA | G16: 20 | H16: 15966.39 | I16: 0 | J16: {=IF($V16="","",IFERROR(INDEX(Articulacion!G:G,$V16),0))} | K16: {=IF($V16="","",IFERROR(INDEX(Articulacion!H:H,$V16),0))} | L16: {=IF($V16="","",IFERROR(INDEX(Articulacion!I:I,$V16),0))} | M16: {=IF($V16="","",IFERROR(INDEX(Articulacion!J:J,$V16),0))} | N16: {=IF($V16="","",IFERROR(INDEX(Articulacion!K:K,$V16),0))} | O16: {=IF($V16="","",IFERROR(INDEX(Articulacion!L:L,$V16),0))} | P16: {=IF($V16="","",IFERROR(INDEX(Articulacion!M:M,$V16),0))} | Q16: {=IF($V16="","",IFERROR(INDEX(Articulacion!N:N,$V16),0))} | R16: {=IF($V16="","",IFERROR(INDEX(Articulacion!O:O,$V16),0))} | S16: {=IF($V16="","",IFERROR(INDEX(Articulacion!P:P,$V16),0))} | T16: {=IF($V16="","",IFERROR(INDEX(Articulacion!Q:Q,$V16),0))} | U16: =IF($V16="",0,SUM(J16:T16)) -> 0 | W16: 10 | X16: 10 | AX16: =SUM(W16:AW16) -> 20 | AY16: =G16-U16-AX16 -> 0
A17: 75 | B17: 275468 | C17: CAJA PARA ARCHIVOS CENTRAL ref: x-200, ref: x-200, rótulo externo de identificación material de construcción: cartón corrugado de pared sencilla con recubrimiento interno especificaciones técnicas, resistencia a la compresión vertical el cartón corrugado debe tener una resistencia a la compresión vertical (rcv) de 790 930 kgf/m | D17: NA | E17: NA | F17: NA | G17: 12 | H17: 7983.19 | I17: 0 | J17: {=IF($V17="","",IFERROR(INDEX(Articulacion!G:G,$V17),0))} | K17: {=IF($V17="","",IFERROR(INDEX(Articulacion!H:H,$V17),0))} | L17: {=IF($V17="","",IFERROR(INDEX(Articulacion!I:I,$V17),0))} | M17: {=IF($V17="","",IFERROR(INDEX(Articulacion!J:J,$V17),0))} | N17: {=IF($V17="","",IFERROR(INDEX(Articulacion!K:K,$V17),0))} | O17: {=IF($V17="","",IFERROR(INDEX(Articulacion!L:L,$V17),0))} | P17: {=IF($V17="","",IFERROR(INDEX(Articulacion!M:M,$V17),0))} | Q17: {=IF($V17="","",IFERROR(INDEX(Articulacion!N:N,$V17),0))} | R17: {=IF($V17="","",IFERROR(INDEX(Articulacion!O:O,$V17),0))} | S17: {=IF($V17="","",IFERROR(INDEX(Articulacion!P:P,$V17),0))} | T17: {=IF($V17="","",IFERROR(INDEX(Articulacion!Q:Q,$V17),0))} | U17: =IF($V17="",0,SUM(J17:T17)) -> 0 | W17: 6 | X17: 6 | AX17: =SUM(W17:AW17) -> 12 | AY17: =G17-U17-AX17 -> 0
A18: 93 | B18: 292167 | C18: Carpeta archivo 2 tapas con refuerzo, Juego de tapas archivo yute, refuerzo tela tamaño oficio, largo 26 centímetros, ancho 37 centímetros, espesor 1 milímetro, normativa del archivo general, entidades públicas y privadas, incluye tapa y contratapa con aleta vertical. Contratapa larga 39 centímetros (37 centímetros más 2 centímetros de aleta; ancho 26 centímetros.) | D18: NA | E18: NA | F18: NA | G18: 30 | H18: 10924.37 | I18: 0 | J18: {=IF($V18="","",IFERROR(INDEX(Articulacion!G:G,$V18),0))} | K18: {=IF($V18="","",IFERROR(INDEX(Articulacion!H:H,$V18),0))} | L18: {=IF($V18="","",IFERROR(INDEX(Articulacion!I:I,$V18),0))} | M18: {=IF($V18="","",IFERROR(INDEX(Articulacion!J:J,$V18),0))} | N18: {=IF($V18="","",IFERROR(INDEX(Articulacion!K:K,$V18),0))} | O18: {=IF($V18="","",IFERROR(INDEX(Articulacion!L:L,$V18),0))} | P18: {=IF($V18="","",IFERROR(INDEX(Articulacion!M:M,$V18),0))} | Q18: {=IF($V18="","",IFERROR(INDEX(Articulacion!N:N,$V18),0))} | R18: {=IF($V18="","",IFERROR(INDEX(Articulacion!O:O,$V18),0))} | S18: {=IF($V18="","",IFERROR(INDEX(Articulacion!P:P,$V18),0))} | T18: {=IF($V18="","",IFERROR(INDEX(Articulacion!Q:Q,$V18),0))} | U18: =IF($V18="",0,SUM(J18:T18)) -> 0 | W18: 2 | X18: 2 | Y18: 1 | Z18: 1 | AA18: 1 | AB18: 1 | AC18: 1 | AD18: 1 | AE18: 1 | AF18: 1 | AG18: 1 | AH18: 1 | AI18: 1 | AJ18: 1 | AK18: 1 | AL18: 1 | AM18: 1 | AN18: 2 | AO18: 1 | AP18: 1 | AQ18: 1 | AR18: 1 | AS18: 1 | AT18: 1 | AU18: 1 | AV18: 1 | AW18: 1 | AX18: =SUM(W18:AW18) -> 30 | AY18: =G18-U18-AX18 -> 0
A19: 74 | B19: 272123 | C19: Carpeta Blanca cuatro (4) aletas, Con una cubierta anterior y una posterior con solapas laterales que doblan al interior. Incluye grafado para 4 pliegues sobre cada solapa. La distancia entre los pliegues es de 1 cm., para obtener diferentes capacidades de almacenamiento. Debe tener un acabado liso, suave, libre de partículas abrasivas u otras imperfecciones. Se recomienda el uso de propalcote desacidificada de mínimo 240 g/m2 o de propalcote de 300 g/m2 o 320 g/m2. Y que cumplan con las siguientes dimensiones., Solapas laterales: (4 aletas) Gramaje 320 Gr. Medidas: Ancho en totalidad 69.5 cm X largo 69,5 cm Base central: ancho 22 Cm X largo 37 cm Base aletas laterales: ancho 25 Cm X largo 35 cm. Base aletas superiores: ancho 22 Cm X largo 17 cm. Grafas (5) con capacidad de hasta 400 folios. Material: Cartulina libre de pulpas lignificadas o recicladas propalcote 320g, Rotuladas con logo del SENA y nombre del Centro (REGIONAL HUILA - Centro de Formación Agroindustrial La Angostura) 1 sola tinta. Recubrimiento: PH neutro o con reserva alcalina. | D19: NA | E19: NA | F19: NA | G19: 87 | H19: 4621.85 | I19: 0 | J19: {=IF($V19="","",IFERROR(INDEX(Articulacion!G:G,$V19),0))} -> 1 | K19: {=IF($V19="","",IFERROR(INDEX(Articulacion!H:H,$V19),0))} -> 1 | L19: {=IF($V19="","",IFERROR(INDEX(Articulacion!I:I,$V19),0))} -> 1 | M19: {=IF($V19="","",IFERROR(INDEX(Articulacion!J:J,$V19),0))} -> 1 | N19: {=IF($V19="","",IFERROR(INDEX(Articulacion!K:K,$V19),0))} -> 1 | O19: {=IF($V19="","",IFERROR(INDEX(Articulacion!L:L,$V19),0))} -> 1 | P19: {=IF($V19="","",IFERROR(INDEX(Articulacion!M:M,$V19),0))} -> 1 | Q19: {=IF($V19="","",IFERROR(INDEX(Articulacion!N:N,$V19),0))} -> 0 | R19: {=IF($V19="","",IFERROR(INDEX(Articulacion!O:O,$V19),0))} -> 0 | S19: {=IF($V19="","",IFERROR(INDEX(Articulacion!P:P,$V19),0))} -> 0 | T19: {=IF($V19="","",IFERROR(INDEX(Articulacion!Q:Q,$V19),0))} -> 0 | U19: =IF($V19="",0,SUM(J19:T19)) -> 7 | V19: 3 | W19: 20 | X19: 20 | Y19: 5 | Z19: 5 | AA19: 5 | AB19: 5 | AC19: 5 | AD19: 5 | AE19: 5 | AF19: 5 | AX19: =SUM(W19:AW19) -> 80 | AY19: =G19-U19-AX19 -> 0
A20: 26 | B20: 279953 | C20: Cartelera de corcho resistente al pinchado constante, de grano puro y uniforme, funcional y durable con marco plástico blanco o verde y esquinas redondeadas, medidas: desde 1.20 x 80 | D20: NA | E20: NA | F20: NA | G20: 1 | H20: 252100.84 | I20: 0 | J20: {=IF($V20="","",IFERROR(INDEX(Articulacion!G:G,$V20),0))} | K20: {=IF($V20="","",IFERROR(INDEX(Articulacion!H:H,$V20),0))} | L20: {=IF($V20="","",IFERROR(INDEX(Articulacion!I:I,$V20),0))} | M20: {=IF($V20="","",IFERROR(INDEX(Articulacion!J:J,$V20),0))} | N20: {=IF($V20="","",IFERROR(INDEX(Articulacion!K:K,$V20),0))} | O20: {=IF($V20="","",IFERROR(INDEX(Articulacion!L:L,$V20),0))} | P20: {=IF($V20="","",IFERROR(INDEX(Articulacion!M:M,$V20),0))} | Q20: {=IF($V20="","",IFERROR(INDEX(Articulacion!N:N,$V20),0))} | R20: {=IF($V20="","",IFERROR(INDEX(Articulacion!O:O,$V20),0))} | S20: {=IF($V20="","",IFERROR(INDEX(Articulacion!P:P,$V20),0))} | T20: {=IF($V20="","",IFERROR(INDEX(Articulacion!Q:Q,$V20),0))} | U20: =IF($V20="",0,SUM(J20:T20)) -> 0 | AS20: 1 | AX20: =SUM(W20:AW20) -> 1 | AY20: =G20-U20-AX20 -> 0
A21: 71 | B21: 235926 | C21: Cartulina 1/8 colores surtidos PAQUETE X 10 UNIDADES. colores de 85cmX25cm | D21: NA | E21: NA | F21: NA | G21: 25 | H21: 4201.68 | I21: 0 | J21: {=IF($V21="","",IFERROR(INDEX(Articulacion!G:G,$V21),0))} -> 4 | K21: {=IF($V21="","",IFERROR(INDEX(Articulacion!H:H,$V21),0))} -> 4 | L21: {=IF($V21="","",IFERROR(INDEX(Articulacion!I:I,$V21),0))} -> 4 | M21: {=IF($V21="","",IFERROR(INDEX(Articulacion!J:J,$V21),0))} -> 4 | N21: {=IF($V21="","",IFERROR(INDEX(Articulacion!K:K,$V21),0))} -> 4 | O21: {=IF($V21="","",IFERROR(INDEX(Articulacion!L:L,$V21),0))} -> 3 | P21: {=IF($V21="","",IFERROR(INDEX(Articulacion!M:M,$V21),0))} -> 2 | Q21: {=IF($V21="","",IFERROR(INDEX(Articulacion!N:N,$V21),0))} -> 0 | R21: {=IF($V21="","",IFERROR(INDEX(Articulacion!O:O,$V21),0))} -> 0 | S21: {=IF($V21="","",IFERROR(INDEX(Articulacion!P:P,$V21),0))} -> 0 | T21: {=IF($V21="","",IFERROR(INDEX(Articulacion!Q:Q,$V21),0))} -> 0 | U21: =IF($V21="",0,SUM(J21:T21)) -> 25 | V21: 4 | AX21: =SUM(W21:AW21) -> 0 | AY21: =G21-U21-AX21 -> 0
A22: 72 | B22: 275471 | C22: Cartulina colores surtidos Tamaño: Pliego 70 x 100 cm. Colores surtidos | D22: NA | E22: NA | F22: NA | G22: 31 | H22: 2100.84 | I22: 0 | J22: {=IF($V22="","",IFERROR(INDEX(Articulacion!G:G,$V22),0))} | K22: {=IF($V22="","",IFERROR(INDEX(Articulacion!H:H,$V22),0))} | L22: {=IF($V22="","",IFERROR(INDEX(Articulacion!I:I,$V22),0))} | M22: {=IF($V22="","",IFERROR(INDEX(Articulacion!J:J,$V22),0))} | N22: {=IF($V22="","",IFERROR(INDEX(Articulacion!K:K,$V22),0))} | O22: {=IF($V22="","",IFERROR(INDEX(Articulacion!L:L,$V22),0))} | P22: {=IF($V22="","",IFERROR(INDEX(Articulacion!M:M,$V22),0))} | Q22: {=IF($V22="","",IFERROR(INDEX(Articulacion!N:N,$V22),0))} | R22: {=IF($V22="","",IFERROR(INDEX(Articulacion!O:O,$V22),0))} | S22: {=IF($V22="","",IFERROR(INDEX(Articulacion!P:P,$V22),0))} | T22: {=IF($V22="","",IFERROR(INDEX(Articulacion!Q:Q,$V22),0))} | U22: =IF($V22="",0,SUM(J22:T22)) -> 0 | W22: 1 | X22: 1 | Y22: 1 | Z22: 1 | AA22: 1 | AB22: 1 | AC22: 1 | AD22: 1 | AE22: 1 | AF22: 1 | AG22: 1 | AH22: 1 | AI22: 1 | AJ22: 1 | AK22: 1 | AL22: 1 | AM22: 1 | AN22: 2 | AO22: 1 | AP22: 1 | AQ22: 1 | AR22: 1 | AS22: 1 | AT22: 2 | AU22: 2 | AV22: 2 | AW22: 1 | AX22: =SUM(W22:AW22) -> 31 | AY22: =G22-U22-AX22 -> 0
A23: 73 | B23: 235926 | C23: Cartulina octavos x 100 unidades Tamaño formato octavo, equivalente a aproximadamente 22 cm x 28 cm, gramaje: Entre 150 g/m² y 180 g/m² según disponibilidad, colores surtidos, superficie lisa y uniforme, rígida, resistente y apta para escritura, impresión y manualidades. Apta para lápiz, marcador, colores, témpera, pegantes y otros materiales escolares. Presentación: Paquete por 100 unidades, empacado y sellado. | D23: NA | E23: NA | F23: NA | G23: 10 | H23: 33613.45 | I23: 0 | J23: {=IF($V23="","",IFERROR(INDEX(Articulacion!G:G,$V23),0))} | K23: {=IF($V23="","",IFERROR(INDEX(Articulacion!H:H,$V23),0))} | L23: {=IF($V23="","",IFERROR(INDEX(Articulacion!I:I,$V23),0))} | M23: {=IF($V23="","",IFERROR(INDEX(Articulacion!J:J,$V23),0))} | N23: {=IF($V23="","",IFERROR(INDEX(Articulacion!K:K,$V23),0))} | O23: {=IF($V23="","",IFERROR(INDEX(Articulacion!L:L,$V23),0))} | P23: {=IF($V23="","",IFERROR(INDEX(Articulacion!M:M,$V23),0))} | Q23: {=IF($V23="","",IFERROR(INDEX(Articulacion!N:N,$V23),0))} | R23: {=IF($V23="","",IFERROR(INDEX(Articulacion!O:O,$V23),0))} | S23: {=IF($V23="","",IFERROR(INDEX(Articulacion!P:P,$V23),0))} | T23: {=IF($V23="","",IFERROR(INDEX(Articulacion!Q:Q,$V23),0))} | U23: =IF($V23="",0,SUM(J23:T23)) -> 0 | AE23: 1 | AF23: 1 | AG23: 1 | AH23: 1 | AI23: 1 | AJ23: 1 | AK23: 1 | AL23: 1 | AM23: 1 | AN23: 1 | AX23: =SUM(W23:AW23) -> 10 | AY23: =G23-U23-AX23 -> 0
A24: 22 | B24: 280058 | C24: Cera para hojas facilita el conteo de hojas y billetes, antibacterial, humectante, no mancha, no tóxico. 20 gramos. | D24: NA | E24: NA | F24: NA | G24: 10 | H24: 7563.03 | I24: 0 | J24: {=IF($V24="","",IFERROR(INDEX(Articulacion!G:G,$V24),0))} | K24: {=IF($V24="","",IFERROR(INDEX(Articulacion!H:H,$V24),0))} | L24: {=IF($V24="","",IFERROR(INDEX(Articulacion!I:I,$V24),0))} | M24: {=IF($V24="","",IFERROR(INDEX(Articulacion!J:J,$V24),0))} | N24: {=IF($V24="","",IFERROR(INDEX(Articulacion!K:K,$V24),0))} | O24: {=IF($V24="","",IFERROR(INDEX(Articulacion!L:L,$V24),0))} | P24: {=IF($V24="","",IFERROR(INDEX(Articulacion!M:M,$V24),0))} | Q24: {=IF($V24="","",IFERROR(INDEX(Articulacion!N:N,$V24),0))} | R24: {=IF($V24="","",IFERROR(INDEX(Articulacion!O:O,$V24),0))} | S24: {=IF($V24="","",IFERROR(INDEX(Articulacion!P:P,$V24),0))} | T24: {=IF($V24="","",IFERROR(INDEX(Articulacion!Q:Q,$V24),0))} | U24: =IF($V24="",0,SUM(J24:T24)) -> 0 | W24: 5 | X24: 5 | AX24: =SUM(W24:AW24) -> 10 | AY24: =G24-U24-AX24 -> 0
A25: 70 | B25: 235764 | C25: Cinta Adhesiva transparente 45 X 40 mts ancha. | D25: NA | E25: NA | F25: NA | G25: 12 | H25: 5042.02 | I25: 0 | J25: {=IF($V25="","",IFERROR(INDEX(Articulacion!G:G,$V25),0))} | K25: {=IF($V25="","",IFERROR(INDEX(Articulacion!H:H,$V25),0))} | L25: {=IF($V25="","",IFERROR(INDEX(Articulacion!I:I,$V25),0))} | M25: {=IF($V25="","",IFERROR(INDEX(Articulacion!J:J,$V25),0))} | N25: {=IF($V25="","",IFERROR(INDEX(Articulacion!K:K,$V25),0))} | O25: {=IF($V25="","",IFERROR(INDEX(Articulacion!L:L,$V25),0))} | P25: {=IF($V25="","",IFERROR(INDEX(Articulacion!M:M,$V25),0))} | Q25: {=IF($V25="","",IFERROR(INDEX(Articulacion!N:N,$V25),0))} | R25: {=IF($V25="","",IFERROR(INDEX(Articulacion!O:O,$V25),0))} | S25: {=IF($V25="","",IFERROR(INDEX(Articulacion!P:P,$V25),0))} | T25: {=IF($V25="","",IFERROR(INDEX(Articulacion!Q:Q,$V25),0))} | U25: =IF($V25="",0,SUM(J25:T25)) -> 0 | W25: 1 | X25: 1 | Y25: 1 | Z25: 1 | AA25: 1 | AB25: 1 | AC25: 1 | AD25: 1 | AE25: 1 | AF25: 1 | AG25: 1 | AH25: 1 | AX25: =SUM(W25:AW25) -> 12 | AY25: =G25-U25-AX25 -> 0
A26: 69 | B26: 272136 | C26: Cinta de enmascarar, ancho 18mm, rollo x 40 metros | D26: NA | E26: NA | F26: NA | G26: 8 | H26: 5462.18 | I26: 0 | J26: {=IF($V26="","",IFERROR(INDEX(Articulacion!G:G,$V26),0))} | K26: {=IF($V26="","",IFERROR(INDEX(Articulacion!H:H,$V26),0))} | L26: {=IF($V26="","",IFERROR(INDEX(Articulacion!I:I,$V26),0))} | M26: {=IF($V26="","",IFERROR(INDEX(Articulacion!J:J,$V26),0))} | N26: {=IF($V26="","",IFERROR(INDEX(Articulacion!K:K,$V26),0))} | O26: {=IF($V26="","",IFERROR(INDEX(Articulacion!L:L,$V26),0))} | P26: {=IF($V26="","",IFERROR(INDEX(Articulacion!M:M,$V26),0))} | Q26: {=IF($V26="","",IFERROR(INDEX(Articulacion!N:N,$V26),0))} | R26: {=IF($V26="","",IFERROR(INDEX(Articulacion!O:O,$V26),0))} | S26: {=IF($V26="","",IFERROR(INDEX(Articulacion!P:P,$V26),0))} | T26: {=IF($V26="","",IFERROR(INDEX(Articulacion!Q:Q,$V26),0))} | U26: =IF($V26="",0,SUM(J26:T26)) -> 0 | AI26: 1 | AJ26: 1 | AK26: 1 | AL26: 1 | AM26: 1 | AN26: 2 | AO26: 1 | AX26: =SUM(W26:AW26) -> 8 | AY26: =G26-U26-AX26 -> 0
A27: 87 | B27: 237623 | C27: Cinta de tela adhesiva, superficie rotulable, para refuerzo y reparación de lomos y cubiertas, material lino libre de ácido, teñido con colores naturales, grosor 2 centímetros. | D27: NA | E27: NA | F27: NA | G27: 11 | H27: 26890.76 | I27: 0 | J27: {=IF($V27="","",IFERROR(INDEX(Articulacion!G:G,$V27),0))} | K27: {=IF($V27="","",IFERROR(INDEX(Articulacion!H:H,$V27),0))} | L27: {=IF($V27="","",IFERROR(INDEX(Articulacion!I:I,$V27),0))} | M27: {=IF($V27="","",IFERROR(INDEX(Articulacion!J:J,$V27),0))} | N27: {=IF($V27="","",IFERROR(INDEX(Articulacion!K:K,$V27),0))} | O27: {=IF($V27="","",IFERROR(INDEX(Articulacion!L:L,$V27),0))} | P27: {=IF($V27="","",IFERROR(INDEX(Articulacion!M:M,$V27),0))} | Q27: {=IF($V27="","",IFERROR(INDEX(Articulacion!N:N,$V27),0))} | R27: {=IF($V27="","",IFERROR(INDEX(Articulacion!O:O,$V27),0))} | S27: {=IF($V27="","",IFERROR(INDEX(Articulacion!P:P,$V27),0))} | T27: {=IF($V27="","",IFERROR(INDEX(Articulacion!Q:Q,$V27),0))} | U27: =IF($V27="",0,SUM(J27:T27)) -> 0 | W27: 5 | X27: 5 | Y27: 1 | AX27: =SUM(W27:AW27) -> 11 | AY27: =G27-U27-AX27 -> 0
A28: 68 | B28: 290227 | C28: Cinta doble Cara Extra Fuerte Vhb Transparente 3m 19mmx5m | D28: NA | E28: NA | F28: NA | G28: 5 | H28: 12605.04 | I28: 0 | J28: {=IF($V28="","",IFERROR(INDEX(Articulacion!G:G,$V28),0))} | K28: {=IF($V28="","",IFERROR(INDEX(Articulacion!H:H,$V28),0))} | L28: {=IF($V28="","",IFERROR(INDEX(Articulacion!I:I,$V28),0))} | M28: {=IF($V28="","",IFERROR(INDEX(Articulacion!J:J,$V28),0))} | N28: {=IF($V28="","",IFERROR(INDEX(Articulacion!K:K,$V28),0))} | O28: {=IF($V28="","",IFERROR(INDEX(Articulacion!L:L,$V28),0))} | P28: {=IF($V28="","",IFERROR(INDEX(Articulacion!M:M,$V28),0))} | Q28: {=IF($V28="","",IFERROR(INDEX(Articulacion!N:N,$V28),0))} | R28: {=IF($V28="","",IFERROR(INDEX(Articulacion!O:O,$V28),0))} | S28: {=IF($V28="","",IFERROR(INDEX(Articulacion!P:P,$V28),0))} | T28: {=IF($V28="","",IFERROR(INDEX(Articulacion!Q:Q,$V28),0))} | U28: =IF($V28="",0,SUM(J28:T28)) -> 0 | W28: 1 | X28: 1 | Y28: 1 | Z28: 1 | AA28: 1 | AX28: =SUM(W28:AW28) -> 5 | AY28: =G28-U28-AX28 -> 0
A29: 66 | B29: 292272 | C29: Clip estándar jumbo Caja X 100 unidades | D29: NA | E29: NA | F29: NA | G29: 5 | H29: 5042.02 | I29: 0 | J29: {=IF($V29="","",IFERROR(INDEX(Articulacion!G:G,$V29),0))} | K29: {=IF($V29="","",IFERROR(INDEX(Articulacion!H:H,$V29),0))} | L29: {=IF($V29="","",IFERROR(INDEX(Articulacion!I:I,$V29),0))} | M29: {=IF($V29="","",IFERROR(INDEX(Articulacion!J:J,$V29),0))} | N29: {=IF($V29="","",IFERROR(INDEX(Articulacion!K:K,$V29),0))} | O29: {=IF($V29="","",IFERROR(INDEX(Articulacion!L:L,$V29),0))} | P29: {=IF($V29="","",IFERROR(INDEX(Articulacion!M:M,$V29),0))} | Q29: {=IF($V29="","",IFERROR(INDEX(Articulacion!N:N,$V29),0))} | R29: {=IF($V29="","",IFERROR(INDEX(Articulacion!O:O,$V29),0))} | S29: {=IF($V29="","",IFERROR(INDEX(Articulacion!P:P,$V29),0))} | T29: {=IF($V29="","",IFERROR(INDEX(Articulacion!Q:Q,$V29),0))} | U29: =IF($V29="",0,SUM(J29:T29)) -> 0 | AB29: 1 | AC29: 1 | AD29: 1 | AE29: 1 | AF29: 1 | AX29: =SUM(W29:AW29) -> 5 | AY29: =G29-U29-AX29 -> 0
A30: 11 | B30: 260817 | C30: Comprobante de ingreso talonario, x, 80, hojas | D30: NA | E30: NA | F30: NA | G30: 1 | H30: 19327.73 | I30: 0 | J30: {=IF($V30="","",IFERROR(INDEX(Articulacion!G:G,$V30),0))} -> 0 | K30: {=IF($V30="","",IFERROR(INDEX(Articulacion!H:H,$V30),0))} -> 0 | L30: {=IF($V30="","",IFERROR(INDEX(Articulacion!I:I,$V30),0))} -> 0 | M30: {=IF($V30="","",IFERROR(INDEX(Articulacion!J:J,$V30),0))} -> 1 | N30: {=IF($V30="","",IFERROR(INDEX(Articulacion!K:K,$V30),0))} -> 0 | O30: {=IF($V30="","",IFERROR(INDEX(Articulacion!L:L,$V30),0))} -> 0 | P30: {=IF($V30="","",IFERROR(INDEX(Articulacion!M:M,$V30),0))} -> 0 | Q30: {=IF($V30="","",IFERROR(INDEX(Articulacion!N:N,$V30),0))} -> 0 | R30: {=IF($V30="","",IFERROR(INDEX(Articulacion!O:O,$V30),0))} -> 0 | S30: {=IF($V30="","",IFERROR(INDEX(Articulacion!P:P,$V30),0))} -> 0 | T30: {=IF($V30="","",IFERROR(INDEX(Articulacion!Q:Q,$V30),0))} -> 0 | U30: =IF($V30="",0,SUM(J30:T30)) -> 1 | V30: 11 | AX30: =SUM(W30:AW30) -> 0 | AY30: =G30-U30-AX30 -> 0
A31: 60 | B31: 278283 | C31: Cosedora Grapadora Metálica De Pinza Alicate Calidad Superior | D31: NA | E31: NA | F31: NA | G31: 5 | H31: 50420.17 | I31: 0 | J31: {=IF($V31="","",IFERROR(INDEX(Articulacion!G:G,$V31),0))} | K31: {=IF($V31="","",IFERROR(INDEX(Articulacion!H:H,$V31),0))} | L31: {=IF($V31="","",IFERROR(INDEX(Articulacion!I:I,$V31),0))} | M31: {=IF($V31="","",IFERROR(INDEX(Articulacion!J:J,$V31),0))} | N31: {=IF($V31="","",IFERROR(INDEX(Articulacion!K:K,$V31),0))} | O31: {=IF($V31="","",IFERROR(INDEX(Articulacion!L:L,$V31),0))} | P31: {=IF($V31="","",IFERROR(INDEX(Articulacion!M:M,$V31),0))} | Q31: {=IF($V31="","",IFERROR(INDEX(Articulacion!N:N,$V31),0))} | R31: {=IF($V31="","",IFERROR(INDEX(Articulacion!O:O,$V31),0))} | S31: {=IF($V31="","",IFERROR(INDEX(Articulacion!P:P,$V31),0))} | T31: {=IF($V31="","",IFERROR(INDEX(Articulacion!Q:Q,$V31),0))} | U31: =IF($V31="",0,SUM(J31:T31)) -> 0 | AN31: 2 | AO31: 1 | AP31: 1 | AQ31: 1 | AX31: =SUM(W31:AW31) -> 5 | AY31: =G31-U31-AX31 -> 0
A32: 64 | B32: 249124 | C32: Cosedora manual, de estructura íntegramente metálica (acero o aleaciones resistentes) papel de hasta 30 hojas, de grapas estándar 26/6 | D32: NA | E32: NA | F32: NA | G32: 17 | H32: 31092.44 | I32: 0 | J32: {=IF($V32="","",IFERROR(INDEX(Articulacion!G:G,$V32),0))} -> 1 | K32: {=IF($V32="","",IFERROR(INDEX(Articulacion!H:H,$V32),0))} -> 0 | L32: {=IF($V32="","",IFERROR(INDEX(Articulacion!I:I,$V32),0))} -> 0 | M32: {=IF($V32="","",IFERROR(INDEX(Articulacion!J:J,$V32),0))} -> 0 | N32: {=IF($V32="","",IFERROR(INDEX(Articulacion!K:K,$V32),0))} -> 0 | O32: {=IF($V32="","",IFERROR(INDEX(Articulacion!L:L,$V32),0))} -> 0 | P32: {=IF($V32="","",IFERROR(INDEX(Articulacion!M:M,$V32),0))} -> 1 | Q32: {=IF($V32="","",IFERROR(INDEX(Articulacion!N:N,$V32),0))} -> 0 | R32: {=IF($V32="","",IFERROR(INDEX(Articulacion!O:O,$V32),0))} -> 0 | S32: {=IF($V32="","",IFERROR(INDEX(Articulacion!P:P,$V32),0))} -> 0 | T32: {=IF($V32="","",IFERROR(INDEX(Articulacion!Q:Q,$V32),0))} -> 0 | U32: =IF($V32="",0,SUM(J32:T32)) -> 2 | V32: 5 | AJ32: 1 | AK32: 1 | AL32: 1 | AM32: 1 | AN32: 2 | AO32: 1 | AP32: 1 | AQ32: 1 | AR32: 1 | AS32: 1 | AT32: 1 | AU32: 1 | AV32: 1 | AW32: 1 | AX32: =SUM(W32:AW32) -> 15 | AY32: =G32-U32-AX32 -> 0
A33: 20 | B33: 280058 | C33: Crayolas extra gruesa paquete por 18 unidades, Colores: varios, Forma: cilíndrica | D33: NA | E33: NA | F33: NA | G33: 7 | H33: 50420.17 | I33: 0 | J33: {=IF($V33="","",IFERROR(INDEX(Articulacion!G:G,$V33),0))} | K33: {=IF($V33="","",IFERROR(INDEX(Articulacion!H:H,$V33),0))} | L33: {=IF($V33="","",IFERROR(INDEX(Articulacion!I:I,$V33),0))} | M33: {=IF($V33="","",IFERROR(INDEX(Articulacion!J:J,$V33),0))} | N33: {=IF($V33="","",IFERROR(INDEX(Articulacion!K:K,$V33),0))} | O33: {=IF($V33="","",IFERROR(INDEX(Articulacion!L:L,$V33),0))} | P33: {=IF($V33="","",IFERROR(INDEX(Articulacion!M:M,$V33),0))} | Q33: {=IF($V33="","",IFERROR(INDEX(Articulacion!N:N,$V33),0))} | R33: {=IF($V33="","",IFERROR(INDEX(Articulacion!O:O,$V33),0))} | S33: {=IF($V33="","",IFERROR(INDEX(Articulacion!P:P,$V33),0))} | T33: {=IF($V33="","",IFERROR(INDEX(Articulacion!Q:Q,$V33),0))} | U33: =IF($V33="",0,SUM(J33:T33)) -> 0 | AQ33: 4 | AR33: 3 | AX33: =SUM(W33:AW33) -> 7 | AY33: =G33-U33-AX33 -> 0
A34: 63 | B34: 290283 | C34: Escarcha líquida colores surtidos frasco 60 ml | D34: NA | E34: NA | F34: NA | G34: 8 | H34: 4621.85 | I34: 0 | J34: {=IF($V34="","",IFERROR(INDEX(Articulacion!G:G,$V34),0))} | K34: {=IF($V34="","",IFERROR(INDEX(Articulacion!H:H,$V34),0))} | L34: {=IF($V34="","",IFERROR(INDEX(Articulacion!I:I,$V34),0))} | M34: {=IF($V34="","",IFERROR(INDEX(Articulacion!J:J,$V34),0))} | N34: {=IF($V34="","",IFERROR(INDEX(Articulacion!K:K,$V34),0))} | O34: {=IF($V34="","",IFERROR(INDEX(Articulacion!L:L,$V34),0))} | P34: {=IF($V34="","",IFERROR(INDEX(Articulacion!M:M,$V34),0))} | Q34: {=IF($V34="","",IFERROR(INDEX(Articulacion!N:N,$V34),0))} | R34: {=IF($V34="","",IFERROR(INDEX(Articulacion!O:O,$V34),0))} | S34: {=IF($V34="","",IFERROR(INDEX(Articulacion!P:P,$V34),0))} | T34: {=IF($V34="","",IFERROR(INDEX(Articulacion!Q:Q,$V34),0))} | U34: =IF($V34="",0,SUM(J34:T34)) -> 0 | AN34: 1 | AO34: 1 | AP34: 1 | AQ34: 1 | AR34: 1 | AS34: 1 | AT34: 1 | AU34: 1 | AX34: =SUM(W34:AW34) -> 8 | AY34: =G34-U34-AX34 -> 0
A35: 62 | B35: 252977 | C35: Folder Blanco Tamaño Carta De 1 1/2 Pulgadas, 3,7cms Ancho | D35: NA | E35: NA | F35: NA | G35: 10 | H35: 22689.08 | I35: 0 | J35: {=IF($V35="","",IFERROR(INDEX(Articulacion!G:G,$V35),0))} | K35: {=IF($V35="","",IFERROR(INDEX(Articulacion!H:H,$V35),0))} | L35: {=IF($V35="","",IFERROR(INDEX(Articulacion!I:I,$V35),0))} | M35: {=IF($V35="","",IFERROR(INDEX(Articulacion!J:J,$V35),0))} | N35: {=IF($V35="","",IFERROR(INDEX(Articulacion!K:K,$V35),0))} | O35: {=IF($V35="","",IFERROR(INDEX(Articulacion!L:L,$V35),0))} | P35: {=IF($V35="","",IFERROR(INDEX(Articulacion!M:M,$V35),0))} | Q35: {=IF($V35="","",IFERROR(INDEX(Articulacion!N:N,$V35),0))} | R35: {=IF($V35="","",IFERROR(INDEX(Articulacion!O:O,$V35),0))} | S35: {=IF($V35="","",IFERROR(INDEX(Articulacion!P:P,$V35),0))} | T35: {=IF($V35="","",IFERROR(INDEX(Articulacion!Q:Q,$V35),0))} | U35: =IF($V35="",0,SUM(J35:T35)) -> 0 | W35: 1 | X35: 1 | Y35: 1 | Z35: 1 | AA35: 1 | AB35: 1 | AC35: 1 | AD35: 1 | AE35: 1 | AF35: 1 | AX35: =SUM(W35:AW35) -> 10 | AY35: =G35-U35-AX35 -> 0
A36: 16 | B36: 292269 | C36: Folders plásticos Tamaño: Carta Espesor del material: Entre 0.18 mm y 0.25 mm, colores surtidos azul, rojo, verde, amarillo, naranja y/o transparente. Tipo sobre o tipo carpeta simple. Bordes termosellados para mayor durabilidad, apertura: Lateral o superior, según diseño del fabricante. Acabado: Superficie lisa o ligeramente texturizada para evitar rayones. Capacidad: Apto para contener entre 20 y 40 hojas de papel bond de 75 g/m². Presentación: Paquete por 6 unidades, empacado y sellado. | D36: NA | E36: NA | F36: NA | G36: 6 | H36: 12605.04 | I36: 0 | J36: {=IF($V36="","",IFERROR(INDEX(Articulacion!G:G,$V36),0))} | K36: {=IF($V36="","",IFERROR(INDEX(Articulacion!H:H,$V36),0))} | L36: {=IF($V36="","",IFERROR(INDEX(Articulacion!I:I,$V36),0))} | M36: {=IF($V36="","",IFERROR(INDEX(Articulacion!J:J,$V36),0))} | N36: {=IF($V36="","",IFERROR(INDEX(Articulacion!K:K,$V36),0))} | O36: {=IF($V36="","",IFERROR(INDEX(Articulacion!L:L,$V36),0))} | P36: {=IF($V36="","",IFERROR(INDEX(Articulacion!M:M,$V36),0))} | Q36: {=IF($V36="","",IFERROR(INDEX(Articulacion!N:N,$V36),0))} | R36: {=IF($V36="","",IFERROR(INDEX(Articulacion!O:O,$V36),0))} | S36: {=IF($V36="","",IFERROR(INDEX(Articulacion!P:P,$V36),0))} | T36: {=IF($V36="","",IFERROR(INDEX(Articulacion!Q:Q,$V36),0))} | U36: =IF($V36="",0,SUM(J36:T36)) -> 0 | AG36: 1 | AH36: 1 | AI36: 1 | AJ36: 1 | AK36: 1 | AL36: 1 | AX36: =SUM(W36:AW36) -> 6 | AY36: =G36-U36-AX36 -> 0
A37: 9 | B37: 292316 | C37: Formato contrato a término indefinido, paquete, x 12, Unidades | D37: NA | E37: NA | F37: NA | G37: 3 | H37: 37815.13 | I37: 0 | J37: {=IF($V37="","",IFERROR(INDEX(Articulacion!G:G,$V37),0))} -> 1 | K37: {=IF($V37="","",IFERROR(INDEX(Articulacion!H:H,$V37),0))} -> 1 | L37: {=IF($V37="","",IFERROR(INDEX(Articulacion!I:I,$V37),0))} -> 1 | M37: {=IF($V37="","",IFERROR(INDEX(Articulacion!J:J,$V37),0))} -> 0 | N37: {=IF($V37="","",IFERROR(INDEX(Articulacion!K:K,$V37),0))} -> 0 | O37: {=IF($V37="","",IFERROR(INDEX(Articulacion!L:L,$V37),0))} -> 0 | P37: {=IF($V37="","",IFERROR(INDEX(Articulacion!M:M,$V37),0))} -> 0 | Q37: {=IF($V37="","",IFERROR(INDEX(Articulacion!N:N,$V37),0))} -> 0 | R37: {=IF($V37="","",IFERROR(INDEX(Articulacion!O:O,$V37),0))} -> 0 | S37: {=IF($V37="","",IFERROR(INDEX(Articulacion!P:P,$V37),0))} -> 0 | T37: {=IF($V37="","",IFERROR(INDEX(Articulacion!Q:Q,$V37),0))} -> 0 | U37: =IF($V37="",0,SUM(J37:T37)) -> 3 | V37: 13 | AX37: =SUM(W37:AW37) -> 0 | AY37: =G37-U37-AX37 -> 0
A38: 8 | B38: 280456 | C38: Formato contrato civil, paquete, x 12, unds | D38: NA | E38: NA | F38: NA | G38: 2 | H38: 36974.79 | I38: 0 | J38: {=IF($V38="","",IFERROR(INDEX(Articulacion!G:G,$V38),0))} -> 1 | K38: {=IF($V38="","",IFERROR(INDEX(Articulacion!H:H,$V38),0))} -> 0 | L38: {=IF($V38="","",IFERROR(INDEX(Articulacion!I:I,$V38),0))} -> 1 | M38: {=IF($V38="","",IFERROR(INDEX(Articulacion!J:J,$V38),0))} -> 0 | N38: {=IF($V38="","",IFERROR(INDEX(Articulacion!K:K,$V38),0))} -> 0 | O38: {=IF($V38="","",IFERROR(INDEX(Articulacion!L:L,$V38),0))} -> 0 | P38: {=IF($V38="","",IFERROR(INDEX(Articulacion!M:M,$V38),0))} -> 0 | Q38: {=IF($V38="","",IFERROR(INDEX(Articulacion!N:N,$V38),0))} -> 0 | R38: {=IF($V38="","",IFERROR(INDEX(Articulacion!O:O,$V38),0))} -> 0 | S38: {=IF($V38="","",IFERROR(INDEX(Articulacion!P:P,$V38),0))} -> 0 | T38: {=IF($V38="","",IFERROR(INDEX(Articulacion!Q:Q,$V38),0))} -> 0 | U38: =IF($V38="",0,SUM(J38:T38)) -> 2 | V38: 14 | AX38: =SUM(W38:AW38) -> 0 | AY38: =G38-U38-AX38 -> 0
A39: 7 | B39: 280456 | C39: formato contrato de trabajo a término fijo, paquete, x 12, Unds | D39: NA | E39: NA | F39: NA | G39: 3 | H39: 35294.12 | I39: 0 | J39: {=IF($V39="","",IFERROR(INDEX(Articulacion!G:G,$V39),0))} -> 1 | K39: {=IF($V39="","",IFERROR(INDEX(Articulacion!H:H,$V39),0))} -> 1 | L39: {=IF($V39="","",IFERROR(INDEX(Articulacion!I:I,$V39),0))} -> 1 | M39: {=IF($V39="","",IFERROR(INDEX(Articulacion!J:J,$V39),0))} -> 0 | N39: {=IF($V39="","",IFERROR(INDEX(Articulacion!K:K,$V39),0))} -> 0 | O39: {=IF($V39="","",IFERROR(INDEX(Articulacion!L:L,$V39),0))} -> 0 | P39: {=IF($V39="","",IFERROR(INDEX(Articulacion!M:M,$V39),0))} -> 0 | Q39: {=IF($V39="","",IFERROR(INDEX(Articulacion!N:N,$V39),0))} -> 0 | R39: {=IF($V39="","",IFERROR(INDEX(Articulacion!O:O,$V39),0))} -> 0 | S39: {=IF($V39="","",IFERROR(INDEX(Articulacion!P:P,$V39),0))} -> 0 | T39: {=IF($V39="","",IFERROR(INDEX(Articulacion!Q:Q,$V39),0))} -> 0 | U39: =IF($V39="",0,SUM(J39:T39)) -> 3 | V39: 15 | AX39: =SUM(W39:AW39) -> 0 | AY39: =G39-U39-AX39 -> 0
A40: 6 | B40: 253827 | C40: Formato hoja de vida sencilla, paquete, x, 10 unidades | D40: NA | E40: NA | F40: NA | G40: 7 | H40: 10084.03 | I40: 0 | J40: {=IF($V40="","",IFERROR(INDEX(Articulacion!G:G,$V40),0))} -> 1 | K40: {=IF($V40="","",IFERROR(INDEX(Articulacion!H:H,$V40),0))} -> 1 | L40: {=IF($V40="","",IFERROR(INDEX(Articulacion!I:I,$V40),0))} -> 1 | M40: {=IF($V40="","",IFERROR(INDEX(Articulacion!J:J,$V40),0))} -> 0 | N40: {=IF($V40="","",IFERROR(INDEX(Articulacion!K:K,$V40),0))} -> 0 | O40: {=IF($V40="","",IFERROR(INDEX(Articulacion!L:L,$V40),0))} -> 0 | P40: {=IF($V40="","",IFERROR(INDEX(Articulacion!M:M,$V40),0))} -> 4 | Q40: {=IF($V40="","",IFERROR(INDEX(Articulacion!N:N,$V40),0))} -> 0 | R40: {=IF($V40="","",IFERROR(INDEX(Articulacion!O:O,$V40),0))} -> 0 | S40: {=IF($V40="","",IFERROR(INDEX(Articulacion!P:P,$V40),0))} -> 0 | T40: {=IF($V40="","",IFERROR(INDEX(Articulacion!Q:Q,$V40),0))} -> 0 | U40: =IF($V40="",0,SUM(J40:T40)) -> 7 | V40: 16 | AX40: =SUM(W40:AW40) -> 0 | AY40: =G40-U40-AX40 -> 0
...

Sheet Articulacion
A1: LINEA | B1: CONSECUTIVO | C1: CODIGO | D1: OBSERVACIONES | E1: CANTIDAD TOTAL | F1: ARTICULACION | G1: 3425230 ASISTENCIA ADMINISTRATIVA | H1: 3425227 ASISTENCIA ADMINISTRATIVA | I1: 3425495 ASISTENCIA ADMINISTRATIVA | J1: 3425231 CONTABILIZACION DE OPERACIONES COMERCIALES Y FINANCIERAS | K1: 3425503 CONTABILIZACION DE OPERACIONES COMERCIALES Y FINANCIERAS | L1: 3425505 CONTABILIZACION DE OPERACIONES COMERCIALES Y FINANCIERAS | M1: 3425511 VENTA DE PRODUCTOS EN LINEA | N1: 3425209 CONSERVACION DE RECURSOS NATURALES | O1: 3425210 CONSERVACION DE RECURSOS NATURALES | P1: 3425504 CONSERVACION DE RECURSOS NATURALES | Q1: 3425222 MONITOREO AMBIENTAL | R1: Total materiales
B2: 1 | C2: 60105410 | D2: Billetes y monedas didácticos pesos colombianos, impresos a color por ambos lados denominaciones $1000, $2000, $5000, $10.000, $20.000, $50.000 y $100.000. Medidas aproximadas 12 cm x 7 cm. Incluye 94 unidades de billetes surtidos y 80 unidades de monedas de cartón surtidas. | E2: 20 | F2: 8 | J2: 2 | K2: 2 | L2: 2 | M2: 2 | R2: =SUM(G2:Q2) -> 8
B3: 2 | C3: 44122003 | D3: Carpeta Blanca cuatro (4) aletas, Con una cubierta anterior y una posterior con solapas laterales que doblan al interior. Incluye grafado para 4 pliegues sobre cada solapa. La distancia entre los pliegues es de 1 cm., para obtener diferentes capacidades de almacenamiento. Debe tener un acabado liso, suave, libre de partículas abrasivas u otras imperfecciones. Se recomienda el uso de propalcore desacidificada de mínimo 240 g/m2 o de propalcote de 300 g/m2 o 320 g/m2. Y que cumplan con las siguientes dimensiones., Solapas laterales: (4 aletas) Gramaje 320 Gr. Medidas: Ancho en totalidad 69.5 cm X largo 69,5 cm Base central: ancho 22 Cm X largo 37 cm Base aletas laterales: ancho 25 Cm X largo 35 cm. Base aletas superiores: ancho 22 Cm X largo 17 cm. Grafas (5) con capacidad de hasta 400 folios. Material: Cartulina libre de pulpas lignificadas o recicladas propalcote 320g, Rotuladas con logo del SENA y nombre del Centro (REGIONAL HUILA - Centro de Formación Agroindustrial La Angostura) 1 sola tinta. Recubrimiento: PH neutro o con reserva alcalina. | E3: 87 | F3: 7 | G3: 1 | H3: 1 | I3: 1 | J3: 1 | K3: 1 | L3: 1 | M3: 1 | R3: =SUM(G3:Q3) -> 7
B4: 3 | C4: 14111519 | D4: Cartulina 1/8 colores surtidos PAQUETE X 10 UNIDADES. colores de 85cmX25cm | E4: 8 | F4: 25 | G4: 4 | H4: 4 | I4: 4 | J4: 4 | K4: 4 | L4: 3 | M4: 2 | R4: =SUM(G4:Q4) -> 25
B5: 4 | C5: 42312009 | D5: Cosedora manual, de estructura íntegramente metálica (acero o aleaciones resistentes) papel de hasta 30 hojas, de grapas estándar 26/6 | E5: 17 | F5: 2 | G5: 1 | M5: 1 | R5: =SUM(G5:Q5) -> 2
B6: 5 | C6: 44121708 | D6: Marcador Punta fina Negro Caja x 14 unidades Marcadores permanentes. Marca en: papel, plástico, metal y en la mayoría de las superficies. Colores intensos. Tinta que seca rápidamente, resistente a la decoloración y agua. | E6: 9 | F6: 1 | I6: 1 | R6: =SUM(G6:Q6) -> 1
B7: 6 | C7: 44121708 | D7: MARCADORES PERMANENTES, colores surtidos, caja x 10 unidades. para uso permanente de secado rápido casi sin olor y resistente al agua, Punta resistente redonda | E7: 13 | F7: 3 | G7: 1 | L7: 1 | M7: 1 | R7: =SUM(G7:Q7) -> 3
B8: 7 | C8: 44121708 | D8: Marcador permanente Tinta negra, punta fina. Caja X 12 unidades. Cuerpo redondo, Punta fina, tinta color negro, Permanente | E8: 12 | F8: 2 | H8: 1 | I8: 1 | R8: =SUM(G8:Q8) -> 2
B9: 8 | C9: 14111506 | D9: Resma de Papel bond tamaño carta, de 500 hojas, Color blanco, 75 gr | E9: 13 | F9: 3 | G9: 1 | K9: 1 | M9: 1 | R9: =SUM(G9:Q9) -> 3
B10: 9 | C10: 60124504 | D10: Rompecabezas Fauna Silvestre 1000pz | E10: 4 | F10: 4 | N10: 1 | O10: 1 | P10: 1 | Q10: 1 | R10: =SUM(G10:Q10) -> 4
B11: 10 | C11: 14111821 | D11: Comprobante de ingreso talonario, x, 80, hojas | E11: 1 | F11: 1 | J11: 1 | R11: =SUM(G11:Q11) -> 1
B12: 11 | C12: 14111808 | D12: Formato pagare paquete x 80 unidades | E12: 1 | F12: 1 | K12: 1 | R12: =SUM(G12:Q12) -> 1
B13: 12 | C13: 14111810 | D13: Formato contrato a término indefinido, paquete, x 12, Unidades | E13: 3 | F13: 3 | G13: 1 | H13: 1 | I13: 1 | R13: =SUM(G13:Q13) -> 3
B14: 13 | C14: 14111810 | D14: Formato contrato civil, paquete, x 12, unds | E14: 2 | F14: 2 | G14: 1 | I14: 1 | R14: =SUM(G14:Q14) -> 2
B15: 14 | C15: 14111810 | D15: formato contrato de trabajo a término fijo, paquete, x 12 , Unds | E15: 3 | F15: 3 | G15: 1 | H15: 1 | I15: 1 | R15: =SUM(G15:Q15) -> 3
B16: 15 | C16: 60105306 | D16: Formato hoja de vida sencilla, paquete, x, 10 unidades | E16: 7 | F16: 7 | G16: 1 | H16: 1 | I16: 1 | M16: 4 | R16: =SUM(G16:Q16) -> 7
B17: 16 | C17: 14111804 | D17: Libreta facturas Libro, de facturas, 1/2, carta | E17: 4 | F17: 4 | J17: 2 | K17: 1 | L17: 1 | R17: =SUM(G17:Q17) -> 4
B18: 17 | C18: 44121701 | D18: Lapicero Retráctil, de alta calidad, Tinta negra, Cuerpo en acrílico denso, Presentación: Caja x 12 unidades | E18: 5 | F18: 5 | G18: 1 | H18: 1 | J18: 1 | K18: 1 | M18: 1 | R18: =SUM(G18:Q18) -> 5
E19: =SUM(E2:E18) -> 209 | F19: =SUM(F2:F18) -> 81 | R19: =SUM(R2:R18) -> 81
